[2023-07-30T18:11:10.596+0300] {processor.py:157} INFO - Started process (PID=28438) to work on /Users/olgastash/airflow/dags/bank_api.py
[2023-07-30T18:11:10.597+0300] {processor.py:826} INFO - Processing file /Users/olgastash/airflow/dags/bank_api.py for tasks to queue
[2023-07-30T18:11:10.597+0300] {logging_mixin.py:150} INFO - [2023-07-30T18:11:10.597+0300] {dagbag.py:541} INFO - Filling up the DagBag from /Users/olgastash/airflow/dags/bank_api.py
[2023-07-30T18:11:10.598+0300] {processor.py:838} WARNING - No viable dags retrieved from /Users/olgastash/airflow/dags/bank_api.py
[2023-07-30T18:11:11.505+0300] {processor.py:182} ERROR - Got an exception! Propagating...
Traceback (most recent call last):
  File "/Library/Frameworks/Python.framework/Versions/3.10/lib/python3.10/site-packages/sqlalchemy/engine/base.py", line 1910, in _execute_context
    self.dialect.do_execute(
  File "/Library/Frameworks/Python.framework/Versions/3.10/lib/python3.10/site-packages/sqlalchemy/engine/default.py", line 736, in do_execute
    cursor.execute(statement, parameters)
sqlite3.OperationalError: no such table: import_error

The above exception was the direct cause of the following exception:

Traceback (most recent call last):
  File "/Library/Frameworks/Python.framework/Versions/3.10/lib/python3.10/site-packages/airflow/dag_processing/processor.py", line 178, in _run_file_processor
    _handle_dag_file_processing()
  File "/Library/Frameworks/Python.framework/Versions/3.10/lib/python3.10/site-packages/airflow/dag_processing/processor.py", line 159, in _handle_dag_file_processing
    result: tuple[int, int] = dag_file_processor.process_file(
  File "/Library/Frameworks/Python.framework/Versions/3.10/lib/python3.10/site-packages/airflow/utils/session.py", line 76, in wrapper
    return func(*args, session=session, **kwargs)
  File "/Library/Frameworks/Python.framework/Versions/3.10/lib/python3.10/site-packages/airflow/dag_processing/processor.py", line 839, in process_file
    DagFileProcessor.update_import_errors(
  File "/Library/Frameworks/Python.framework/Versions/3.10/lib/python3.10/site-packages/airflow/api_internal/internal_api_call.py", line 112, in wrapper
    return func(*args, **kwargs)
  File "/Library/Frameworks/Python.framework/Versions/3.10/lib/python3.10/site-packages/airflow/utils/session.py", line 73, in wrapper
    return func(*args, **kwargs)
  File "/Library/Frameworks/Python.framework/Versions/3.10/lib/python3.10/site-packages/airflow/dag_processing/processor.py", line 620, in update_import_errors
    existing_import_error_files = [x.filename for x in session.query(errors.ImportError.filename).all()]
  File "/Library/Frameworks/Python.framework/Versions/3.10/lib/python3.10/site-packages/sqlalchemy/orm/query.py", line 2773, in all
    return self._iter().all()
  File "/Library/Frameworks/Python.framework/Versions/3.10/lib/python3.10/site-packages/sqlalchemy/orm/query.py", line 2916, in _iter
    result = self.session.execute(
  File "/Library/Frameworks/Python.framework/Versions/3.10/lib/python3.10/site-packages/sqlalchemy/orm/session.py", line 1717, in execute
    result = conn._execute_20(statement, params or {}, execution_options)
  File "/Library/Frameworks/Python.framework/Versions/3.10/lib/python3.10/site-packages/sqlalchemy/engine/base.py", line 1710, in _execute_20
    return meth(self, args_10style, kwargs_10style, execution_options)
  File "/Library/Frameworks/Python.framework/Versions/3.10/lib/python3.10/site-packages/sqlalchemy/sql/elements.py", line 334, in _execute_on_connection
    return connection._execute_clauseelement(
  File "/Library/Frameworks/Python.framework/Versions/3.10/lib/python3.10/site-packages/sqlalchemy/engine/base.py", line 1577, in _execute_clauseelement
    ret = self._execute_context(
  File "/Library/Frameworks/Python.framework/Versions/3.10/lib/python3.10/site-packages/sqlalchemy/engine/base.py", line 1953, in _execute_context
    self._handle_dbapi_exception(
  File "/Library/Frameworks/Python.framework/Versions/3.10/lib/python3.10/site-packages/sqlalchemy/engine/base.py", line 2134, in _handle_dbapi_exception
    util.raise_(
  File "/Library/Frameworks/Python.framework/Versions/3.10/lib/python3.10/site-packages/sqlalchemy/util/compat.py", line 211, in raise_
    raise exception
  File "/Library/Frameworks/Python.framework/Versions/3.10/lib/python3.10/site-packages/sqlalchemy/engine/base.py", line 1910, in _execute_context
    self.dialect.do_execute(
  File "/Library/Frameworks/Python.framework/Versions/3.10/lib/python3.10/site-packages/sqlalchemy/engine/default.py", line 736, in do_execute
    cursor.execute(statement, parameters)
sqlalchemy.exc.OperationalError: (sqlite3.OperationalError) no such table: import_error
[SQL: SELECT import_error.filename AS import_error_filename 
FROM import_error]
(Background on this error at: https://sqlalche.me/e/14/e3q8)
